Workbook

Sheet Grunddata
A1: Butik | B1: Nr | C1: Region | D1: Postadress | E1: Postnr / Ort | F1: Butikens telefon nr | G1: Handlare/Butikschef Egenägd | H1: Handlare/BC mobil nr (ej sms till BC egenägd) | I1: Mejladress Handlare/BC | J1: Butikschef Handlarägd | K1: Mobil/SMS | L1: Besöksadress | M1: Leveransadress | N1: Ort | O1: Org.nr | P1: Bolagsnamn | Q1: Telefon | R1: Ägandeform | S1: PostNord
A2: Associerad Börjes Tingsryd | B2: 4761 | C2: Syd Handlarägd | D2: Box 7 | E2: 362 21 Tingsryd | F2: 0477-482 00 | G2: Anna Rungegård | H2: 0477-482 00 | I2: anna.rungegard@hemkop.se ; pernilla.malm@hemkop.se | J2: Pernilla Malm | L2: Storgatan 66-68 | M2: Storgatan 66-68 | N2: 362 30 Tingsryd | O2: 556074-9151 | P2: Börjes Tingsryd AB | R2: Associerad | S2: Får ej beställa via Axfoods fraktavtal
A3: Associerad Extra Mjällby Listerlandet | B3: 4597 | C3: Syd Handlarägd | D3: Remelinvägen 4a | E3: 294 00 Sölvesborg | F3: 0456-548 70 | G3: Albin Håkansson | H3: 070-7749171 | I3: albin.hakansson@butikskontakt.se | L3: Remelinvägen 4a | M3: Remelinvägen 4a | N3: 294 00 Sölvesborg | O3: 556430-8087 | P3: Listerhallen AB | R3: Associerad | S3: Får ej beställa via Axfoods fraktavtal
A4: Associerad Fittja Matmarknad Norsborg | B4: 4759 | C4: Stockholm 2 - Mitt Handlarägd | D4: Fittja Torg 21 | E4: 145 51 Norsborg | F4: 08-740 13 37 | G4: Resül Yetim | H4: 073-9800583 | I4: resul.yetim@hemkop.se | L4: Fittja Torg 21 | M4: Fittja Torg 21 | N4: 145 51 Norsborg | O4: 556805-6716 | P4: Munir´s Livs AB | R4: Associerad | S4: Får ej beställa via Axfoods fraktavtal
A5: Associerad Fresha Stockholm Hässelby | B5: 4764 | C5: Stockholm 1 Handlarägd | D5: Hässelby Torg 7 | E5: 165 55 Hässelby | F5: 073-9975400 | G5: Savyo Markus / Stivan Marqus | H5: 073-9975400 | I5: savyo.markus@butikskontakt.se ; sm-matbutik@hotmail.com | L5: Hässelby Torg 7 | M5: Hässelby Torg 7 | N5: 165 55 Hässelby | O5: 559281-2365 | P5: SM Matbutik AB | R5: Associerad | S5: Får ej beställa via Axfoods fraktavtal
A6: Associerad Hemköp Gråbo Bonum | B6: 4936 | C6: Väst Handlarägd | D6: Mjörnbotorget 2 | E6: 443 42 Gråbo | F6: 030-241 265 | G6: Svante Kedner | H6: 070-514 13 25 | I6: svante.kedner@hemkop.se | L6: Mjörnbotorget 2 | M6: Mjörnbotorget 2 | N6: 443 42 Gråbo | O6: 556174-9804 | P6: Bonum Livsmedel i Gråbo AB | R6: Associerad | S6: Får ej beställa via Axfoods fraktavtal
A7: Associerad Hovsjö Matcenter | B7: 4749 | C7: Stockholm 1 Handlarägd | D7: Björnövägen 10 | E7: 151 65 Södertälje | F7: 08-550 411 08 | G7: Leden Shamoon | H7: 070-4674227 | I7: leden.shamoon@butikskontakt.se | J7: Kyara Somo | K7: 070-024 77 78 | L7: Björnövägen 10 | M7: Björnövägen 10 | N7: 151 65 Södertälje | O7: 559089-2542 | P7: Hovsö Närlivs AB | R7: Associerad | S7: Får ej beställa via Axfoods fraktavtal
A8: Associerad Hörby Lågprisaffär | B8: 4602 | C8: Syd Handlarägd | D8: Nygatan 29 | E8: 242 33 Hörby | F8: 0415-103 23 | G8: Bengt V Hansson | H8: 070-5110112 | I8: bengt.hansson@butikskontakt.se | L8: Nygatan 29 | M8: Nygatan 29 | N8: 242 33 Hörby | O8: 430818-3716 | P8: Hörby Lågprisaffär | R8: Associerad | S8: Får ej beställa via Axfoods fraktavtal
A9: Associerad Ingaröhallen Brunn | B9: 4653 | C9: Stockholm 2 - Mitt Handlarägd | D9: Pastor Ödmans Väg 2 | E9: 134 60 Ingarö | F9: 08-57 44 06 40 | G9: Johan Edlund | H9: 070-9266211 | I9: johan.edlund@butikskontakt.se | J9: Katja Wallin | K9: 0708 28 23 16 | L9: Pastor Ödmans Väg 2 | M9: Pastor Ödmans Väg 2 | N9: 134 60 Ingarö | O9: 556657-6236 | P9: Ingaröhallen AB | R9: Associerad | S9: Får ej beställa via Axfoods fraktavtal
A10: Associerad Lågprisvaruhuset MEJK Lindesberg | B10: 4769 | C10: Norr Handlarägd | D10: Bandygatan 2C | E10: 711 34 Lindesberg | F10: 0581-10046 | G10: Mikael Karlsson | H10: 070-6747180 | I10: mikael.karlsson@butikskontakt.se | L10: Bandygatan 2C | M10: Bandygatan 2C | N10: 711 34 Lindesberg | O10: 556544-3404 | P10: MEJK Butiken AB | R10: Associerad | S10: Får ej beställa via Axfoods fraktavtal
A11: Associerad Matköp Tumba Storvreten | B11: 4619 | C11: Stockholm 1 Handlarägd | D11: Storvretsvägen 13 | E11: 147 54 Tumba | F11: 08-530 302 80 | G11: Georgez Tannous | H11: 070-4832987 | I11: georgez.tannous@butikskontakt.se | L11: Storvretsvägen 13 | M11: Storvretsvägen 13 | N11: 147 54 Tumba | O11: 556698-3648 | P11: Al Arez AB | R11: Associerad | S11: Får ej beställa via Axfoods fraktavtal
A12: Associerad Matvärlden Kungens Kurva | B12: 4765 | C12: Stockholm 2 - Mitt Handlarägd | D12: Tangentvägen 14 A | E12: 141 75 Kungens Kurva | F12: 08-124 383 00 | G12: Muhittin Tayli | H12: 0704-945626 | I12: jt@matvarlden.se ; jonas.tayli@butikskontakt.se | L12: Tangentvägen 14 A | M12: Tangentvägen 14 B | N12: 141 75 Kungens Kurva | O12: 559348-7126 | P12: Matvärlden Kungens Kurva AB | R12: Associerad | S12: Får ej beställa via Axfoods fraktavtal
A13: Associerad Matvärlden Veddesta | B13: 4744 | C13: Stockholm 2 - Mitt Handlarägd | D13: Nettovägen 2-4 | E13: 175 41 Järfälla | F13: 08-409 360 00 | G13: Muhittin Tayli | H13: 0704-945626 | I13: jt@matvarlden.se ; jonas.tayli@butikskontakt.se | J13: Mattias Hedberg | K13: 070-9296570 | L13: Nettovägen 2-4 | M13: Nettovägen 2-4 | N13: 175 41 Järfälla | O13: 556969-4754 | P13: Matvärlden Veddesta AB | R13: Associerad | S13: Får ej beställa via Axfoods fraktavtal
A14: Associerad Polargrossen Haparanda | B14: 4696 | C14: Norr Handlarägd | D14: Norra Industrivägen 1 | E14: 953 34 Haparanda | G14: Kari Lantto | H14: 070-5174372 | I14: kari.lantto@polargrossen.se | J14: juho.ikonen@polargrossen.se | L14: Norra Industrivägen 1 | M14: Norra Industrivägen 1 | N14: 953 34 Haparanda | O14: 556576-4759 | P14: Polargrossen AB | R14: Associerad | S14: Får ej beställa via Axfoods fraktavtal
A15: Associerad T-Snabben Stockholm Östra Station | B15: 4692 | C15: Stockholm 1 Handlarägd | D15: Valhallavägen 77 | E15: 114 27 Stockholm | F15: 08-612 18 95 | G15: Frank Thelin | H15: 070-9323920 | I15: frank.thelin@hemkop.se; eva.pettersson@butikskontakt.se | J15: Eva Pettersson | L15: Valhallavägen 77 | M15: Valhallavägen 77 | N15: 114 27 Stockholm | O15: 556986-2427 | P15: Food Market T-Snabben AB | Q15: 08 612 18 95 | R15: Associerad | S15: Får ej beställa via Axfoods fraktavtal
A16: Hemköp Alfta Västanågatan | B16: 4798 | C16: Norr Handlarägd | D16: Västanågatan 3 | E16: 822 31 Alfta | F16: 0271-552 30 | G16: Lena-Marie Persson | H16: 070-5523066 | I16: lena-marie.persson@hemkop.se | J16: Mikael Persson | L16: Västanågatan 3 | M16: Västanågatan 3 | N16: 822 31 Alfta | O16: 559019-8858 | P16: Lena-Maries Livs AB | Q16: 0271-552 30 | R16: Handlarägd | S16: Får ej beställa via Axfoods fraktavtal
A17: Hemköp Alingsås Sveagatan | B17: 4660 | C17: Väst Handlarägd | D17: Sveagatan 8 | E17: 441 32 Alingsås | F17: 0322-61 19 77 | G17: Krister Nordgren/Ros-Mari Abrahamsson | H17: 070-6300049/070-3633047 | I17: krister.nordgren@hemkop.se | L17: Sveagatan 8 | M17: Sveagatan 8 | N17: 441 32 Alingsås | O17: 556885-7162 | P17: Rastor AB | R17: Handlarägd | S17: Får ej beställa via Axfoods fraktavtal
A18: Hemköp Avesta Prästgatan | B18: 4797 | C18: Norr Handlarägd | D18: Prästgatan 26 | E18: 774 33 Avesta | F18: 0226 - 526 40 | G18: Kristoffer Pettersson | H18: 070-4903117 | I18: kristoffer.pettersson@hemkop.se | L18: Prästgatan 26 | M18: Prästgatan 26 | N18: 774 33 Avesta | O18: 559019-8825 | P18: KEKP Mat AB | Q18: 0226-526 40 | R18: Handlarägd | S18: Får ej beställa via Axfoods fraktavtal
A19: Hemköp Avesta Skogsbo | B19: 4714 | C19: Norr Handlarägd | D19: Rutboleden 1 | E19: 774 40 Avesta | F19: 0226-174 410 | G19: Peter Bergvall | H19: 070-6830132 | I19: peter.bergvall@hemkop.se | K19: 0703 55 22 55 | L19: Rutboleden 1 | N19: 774 40 Avesta | O19: 556780-7036 | P19: Mataffär´n i Skogsbo AB | R19: Handlarägd | S19: Får ej beställa via Axfoods fraktavtal
A20: Hemköp Stockholm Bromma Stora Mossen | B20: 4774 | C20: Stockholm 1 Handlarägd | D20: SOBELGRÄND 4 | E20: 167 58 Bromma | F20: 08-12437960 | G20: Jakob Garpe | H20: 070-3939099 | I20: jakob.garpe@hemkop.se | L20: SOBELGRÄND 4 | M20: SOBELGRÄND 4 | N20: 167 58 Bromma | O20: 5593398307 | P20: Hemköp I Bromma AB | R20: 91/9
A21: Hemköp Björklinge C | B21: 4514 | C21: Norr Handlarägd | D21: Södra Långgatan 4 | E21: 743 62 Björklinge | F21: 018-37 00 25 | G21: David Jonegård / Andreas/Johannes Lindgren | H21: 073-9485368 / 073-7251256 / 070-0809562 | I21: david.jonegard@hemkop.se;andreas.lindgren@hemkop.se;johannes.lindgren@hemkop.se | L21: Södra Långåvägen 4 | M21: Södra Långåvägen 4 | N21: 743 62 Björklinge | O21: 556514-6395 | P21: Björkhallen i Björklinge AB | R21: Handlarägd | S21: Får ej beställa via Axfoods fraktavtal
A22: Hemköp Bollebygd Stationsvägen | B22: 4515 | C22: Syd Handlarägd | D22: Stationsvägen 7 | E22: 517 23 Bollebygd | F22: 033-20 42 60 | G22: Lars Wiss | H22: 070-6070648 | I22: lars.wiss@hemkop.se | L22: Stationsvägen 7 | M22: Stationsvägen 7 | N22: 517 23 Bollebygd | O22: 556352-0245 | P22: Bollebygds Stormarknad Nya AB | Q22: 033-20 42 65 | R22: Handlarägd | S22: Får ej beställa via Axfoods fraktavtal
A23: Hemköp Borlänge Södra Backa | B23: 4638 | C23: Norr Handlarägd | D23: Hammargatan 8 | E23: 781 71 Borlänge | F23: 0243-680 00 | G23: Monica Jörgensen | H23: 070-2442118 | I23: monica.jorgensen@hemkop.se | J23: Monica Jörgensen | K23: 0702 44 21 18 | L23: Hammargatan 8 | M23: Hammargatan 8 | N23: 781 71 Borlänge | O23: 556524-2814 | P23: Mathuset i Södra Backa AB | Q23: 0243-680 00/070-666 84 64 | R23: Handlarägd | S23: Får ej beställa via Axfoods fraktavtal
A24: Hemköp Bålsta Gamla C | B24: 4609 | C24: Norr Handlarägd | D24: Stockholmsvägen 14 | E24: 746 33 Bålsta | F24: 0171-500 06 | G24: Calle Lindqvist | H24: 072-3111029 | I24: calle.lindqvist@hemkop.se | L24: Stockholmsvägen 14 | M24: Stockholmsvägen 14 | N24: 746 33 Bålsta | O24: 556298-8674 | P24: Lindqvist Handel AB | R24: Handlarägd | S24: Får ej beställa via Axfoods fraktavtal
A25: Hemköp Dala-Järna Myrbacka | B25: 4773 | C25: Norr Handlarägd | D25: Myrbacka 80 | E25: 786 72 Dala-Järna | F25: 0281-200 01 | G25: Niclas Dahlman | H25: 070-7676275 | I25: niclas.dahlman@hemkop.se | L25: Myrbacka 80 | M25: Myrbacka 80 | N25: 786 72 Dala-Järna | O25: 559506-8981 | P25: Dahlmat AB | Q25: 0281- 200 01 | R25: Handlarägd | S25: Får ej beställa via Axfoods fraktavtal
A26: Hemköp Dalby C | B26: 4517 | C26: Syd Handlarägd | D26: Kristers väg 23 | E26: 247 50 Dalby | F26: 046-20 00 77 | G26: Magnus Holm | H26: 070-2850760 | I26: magnus.holm@hemkop.se | L26: Kristers väg 23 | M26: Kristers väg 23 | N26: 247 50 Dalby | O26: 556700-9344 | P26: Magnus Holms livs i Dalby AB | R26: Handlarägd | S26: Får ej beställa via Axfoods fraktavtal
A27: Hemköp Danderyd Mörby C | B27: 4239 | C27: Stockholm Egenägd | D27: Golfvägen 2 | E27: 182 31 Danderyd | F27: 08-755 00 77 | G27: Linus Edestav | H27: 010-4744239 | I27: butikschef.hemkopmorbyc.4239@hemkop.se | K27: 0761 09 06 59 | L27: Mörby Centrum | M27: Mörbyleden 6 | N27: 182 31 Danderyd | O27: 556113-8826 | P27: Hemköpskedjan AB | Q27: 08- 544 907 58 | R27: Egenägd
A28: Hemköp Delsbo Edevägen | B28: 4667 | C28: Norr Handlarägd | D28: Edevägen 9 | E28: 820 60 Delsbo | F28: 0653-100 03 | G28: Christer Jonsson | H28: 072-5779507 | I28: christer.jonsson@hemkop.se | L28: Edevägen 9 | M28: Edevägen 9 | N28: 820 60 Delsbo | O28: 556885-9507 | P28: Handel & Service i BjuråkerAB | R28: Handlarägd | S28: Får ej beställa via Axfoods fraktavtal
A29: Hemköp Ellös Rosenlundsvägen | B29: 4519 | C29: Väst Handlarägd | D29: Rosenlundsvägen 51 | E29: 474 31 Ellös | F29: 0304-500 51 | G29: Samir Cherif | H29: 070-7427200 | I29: samir.cherif@hemkop.se | J29: Markus Olsson | K29: 072-388 821 00 | L29: Rosenlundsvägen 51 | M29: Rosenlundsvägen 51 | N29: 474 31 Ellös | O29: 556769-4814 | P29: Citybutikerna i Ellös AB | Q29: 0304-50051 | R29: Handlarägd | S29: Får ej beställa via Axfoods fraktavtal
A30: Hemköp Eskilstuna C | B30: 4221 | C30: Mitt Egenägd | D30: Rademacherg. 5-7 | E30: 632 20 Eskilstuna | F30: 016-13 10 40 | G30: Erik Johansson Englund | H30: 010-4744221 | I30: butikschef.hemkopeskilstunac.4221@hemkop.se | K30: 0761 09 06 12 | L30: Rademacherg. 5-7 | M30: Rademacherg. 5-7 | N30: 632 20 Eskilstuna | O30: 556113-8826 | P30: Hemköpskedjan AB | R30: Egenägd
A31: Hemköp Falun C | B31: 4203 | C31: Stockholm-Norr Egenägd | D31: Holmgatan 18 | E31: 791 71 Falun | F31: 023-268 50 | G31: Jonas Thunstedt | H31: 010-4744203 | I31: butikschef.hemkopfalunc.4203@hemkop.se | K31: 0761 09 06 14 | L31: Holmgatan 18 | M31: Holmgatan 18 | N31: 791 71 Falun | O31: 556113-8826 | P31: Hemköpskedjan AB | R31: Egenägd
A32: Hemköp Falun Hosjö | B32: 4687 | C32: Norr Handlarägd | D32: Centralvägen 7 | E32: 791 46 Falun | F32: 023-320 84 | G32: Andreas Nygårdh | H32: 070-0909987 | I32: andreas.nygardh@hemkop.se | L32: Centralvägen 7 | M32: Centralvägen 7 | N32: 791 46 Falun | O32: 556961-5627 | P32: Mat i Hosjö AB | R32: Handlarägd | S32: Får ej beställa via Axfoods fraktavtal
A33: Hemköp Fellingsbro C | B33: 4520 | C33: Norr Handlarägd | D33: Hemvägen | E33: 732 71 Fellingsbro | F33: 0581-62 00 53 | G33: Andreas Fredriksson | H33: 070-2423352 | I33: andreas.fredriksson@hemkop.se | L33: Hemvägen | M33: Hemvägen | N33: 732 71 Fellingsbro | O33: 556616-0072 | P33: Anforina AB | R33: Handlarägd | S33: Får ej beställa via Axfoods fraktavtal
A34: Hemköp Gnesta Dansutvägen | B34: 4521 | C34: Stockholm 2 - Mitt Handlarägd | D34: Dansutvägen 2 | E34: 646 30 Gnesta | F34: 0158-262 75 | G34: Andreas Norlin | H34: 073-6602931 | I34: andreas.norlin@hemkop.se | J34: Stefan Andersson | K34: 0705 92 76 60 | L34: Dansutvägen 2 | M34: Dansutvägen 2 | N34: 646 30 Gnesta | O34: 556581-4778 | P34: Stopp Matmarknad i Gnesta AB | Q34: 0158-262 75/073-388 78 29 | R34: Handlarägd | S34: Får ej beställa via Axfoods fraktavtal
A35: Hemköp Grums Orrby | B35: 4930 | C35: Norr Handlarägd | D35: Orrkullegatan 2 | E35: 64 31 Grums | F35: 0555-430 40 | G35: Krister Lennartsson | H35: 070-2390388 | I35: krister.lennartsson@hemkop.se | L35: Orrkullegatan 2 | M35: Orrkullegatan 2 | N35: 664 31 Grums | O35: 559520-6474 | P35: HK Grums AB | R35: Handlarägd | S35: Får ej beställa via Axfoods fraktavtal
A36: Hemköp Grästorp Södergatan | B36: 4524 | C36: Väst Handlarägd | D36: Södergatan 27 | E36: 467 30 Grästorp | F36: 0514-589 99 | G36: Andreas Lindahl | H36: 073-0373849 | I36: andreas.lindahl@hemkop.se | J36: Sofie Nilsson | L36: Södergatan 27 | M36: Södergatan 27 | N36: 467 30 Grästorp | O36: 556137-8679 | P36: Lindahls Vinstköp AB | Q36: 0514-58999 | R36: Handlarägd | S36: Får ej beställa via Axfoods fraktavtal
A37: Hemköp Gustavsberg Hamnen | B37: 4670 | C37: Stockholm 1 Handlarägd | D37: Odelsbergs väg 1 | E37: 134 40 Gustavsberg | F37: 08-570 35 650 | G37: Stephan Johnsson | H37: 070-7294916 | I37: stephan@affarsbyggarna.se;anders@affarsbyggarna.se; david.valentin@hemkop.se | J37: David Valentin | K37: 0704 32 36 14 | L37: Odelsbergs väg 1 | M37: Odelsbergs väg 1 | N37: 134 40 Gustavsberg | O37: 556910-7799 | P37: Hamnens Livs AB | Q37: 073-716 16 88 | R37: Handlarägd | S37: Får ej beställa via Axfoods fraktavtal
A38: Hemköp Göteborg Annedal | B38: 4512 | C38: Väst Handlarägd | D38: Brunnsgatan 5 | E38: 413 12 Göteborg | F38: 031-41 86 05 | G38: Ulf Törnestrand | H38: 070-8117298 | I38: ulf.tornestrand@hemkop.se | J38: Antonia Törnerstrand | K38: 031-41 86 05 | L38: Brunnsgatan 5 | M38: Brunnsgatan 5 | N38: 413 12 Göteborg | O38: 556235-3150 | P38: Ulf Törnestrand AB | Q38: 031-41 86 05 ank 613 | R38: Handlarägd | S38: Får ej beställa via Axfoods fraktavtal
A39: Hemköp Göteborg Frölunda Torg | B39: 4353 | C39: Göteborg Egenägd | D39: Marconigatan lastkaj 10 | E39: 421 44 Västra Frölunda | F39: 031-734 36 00 | G39: Annika Pantzar | H39: 010-4744353 | I39: butikschef.hemkopgoteborgfrolundatorg.4353@hemkop.se | K39: 0761 09 06 17 | L39: Marconigatan lastkaj 10 | M39: Marconigatan lastkaj 10 | N39: 421 44 Västra Frölunda | O39: 556113-8826 | P39: Hemköpskedjan AB | Q39: 031-734 36 28 | R39: Egenägd
A40: Hemköp Göteborg Guldheden | B40: 4264 | C40: Göteborg Egenägd | D40: Dr Fries torg | E40: 413 23 Göteborg | F40: 031-82 25 06 | G40: Fredrik Pehrson | H40: 010-4744264 | I40: butikschef.hemkopgoteborgguldheden.4264@hemkop.se | L40: Dr Fries torg | M40: Dr Fries torg | N40: 413 23 Göteborg | O40: 556068-3509 | P40: AB Jiffy | Q40: 070-4805946 | R40: Egenägd
...

Sheet Organisationsobjekt steg 1
A1: Objektnamn | B1: Objektherarkiskt intrimnumer | C1: Överordnat objekt intrim
A2: Axfood Sverige | B2: 1 | C2: -
A3: Hemköp kedjan | B3: 2 | C3: 1
A4: Göteborg Egenägd | B4: 3 | C4: 2
A5: Mitt Egenägd | B5: 4 | C5: 2
A6: Norr Handlarägd | B6: 5 | C6: 2
A7: Stockholm 1 Handlarägd | B7: 6 | C7: 2
A8: Stockholm 2 - Mitt Handlarägd | B8: 7 | C8: 2
A9: Stockholm Egenägd | B9: 8 | C9: 2
A10: Stockholm-Norr Egenägd | B10: 9 | C10: 2
A11: Syd Egenägd | B11: 10 | C11: 2
A12: Syd Handlarägd | B12: 11 | C12: 2
A13: Väst Handlarägd | B13: 12 | C13: 2

Sheet Butiksobjekt steg 2
B1: Fasta objektimportfält | H1: Metadata
H2: Region (Metadata asociationsnamn) | I2: Butikschef
A3: Intrumnummer | B3: Objektnamn | C3: Intrumnummer | D3: Överordnat objekt | E3: Postadress | F3: Postnr | G3: Ort | H3: Region | I3: Namn | J3: Telefon | K3: E-post
A4: 1 | B4: Associerad Börjes Tingsryd | C4: 1 | D4: 11 | E4: Box 7 | F4: 362 21 | G4: Tingsryd | H4: Syd Handlarägd | I4: Anna Rungegård | J4: 0477-482 00 | K4: anna.rungegard@hemkop.se ; pernilla.malm@hemkop.se
A5: 2 | B5: Associerad Extra Mjällby Listerlandet | C5: 2 | D5: 11 | E5: Remelinvägen 4a | F5: 294 00 | G5: Sölvesborg | H5: Syd Handlarägd | I5: Albin Håkansson | J5: 070-7749171 | K5: albin.hakansson@butikskontakt.se
A6: 3 | B6: Associerad Fittja Matmarknad Norsborg | C6: 3 | D6: 7 | E6: Fittja Torg 21 | F6: 145 51 | G6: Norsborg | H6: Stockholm 2 - Mitt Handlarägd | I6: Resül Yetim | J6: 073-9800583 | K6: resul.yetim@hemkop.se
A7: 4 | B7: Associerad Fresha Stockholm Hässelby | C7: 4 | D7: 6 | E7: Hässelby Torg 7 | F7: 165 55 | G7: Hässelby | H7: Stockholm 1 Handlarägd | I7: Savyo Markus / Stivan Marqus | J7: 073-9975400 | K7: savyo.markus@butikskontakt.se ; sm-matbutik@hotmail.com
A8: 5 | B8: Associerad Hemköp Gråbo Bonum | C8: 5 | D8: 12 | E8: Mjörnbotorget 2 | F8: 443 42 | G8: Gråbo | H8: Väst Handlarägd | I8: Svante Kedner | J8: 070-514 13 25 | K8: svante.kedner@hemkop.se
A9: 6 | B9: Associerad Hovsjö Matcenter | C9: 6 | D9: 6 | E9: Björnövägen 10 | F9: 151 65 | G9: Södertälje | H9: Stockholm 1 Handlarägd | I9: Leden Shamoon | J9: 070-4674227 | K9: leden.shamoon@butikskontakt.se
A10: 7 | B10: Associerad Hörby Lågprisaffär | C10: 7 | D10: 11 | E10: Nygatan 29 | F10: 242 33 | G10: Hörby | H10: Syd Handlarägd | I10: Bengt V Hansson | J10: 070-5110112 | K10: bengt.hansson@butikskontakt.se
A11: 8 | B11: Associerad Ingaröhallen Brunn | C11: 8 | D11: 7 | E11: Pastor Ödmans Väg 2 | F11: 134 60 | G11: Ingarö | H11: Stockholm 2 - Mitt Handlarägd | I11: Johan Edlund | J11: 070-9266211 | K11: johan.edlund@butikskontakt.se
A12: 9 | B12: Associerad Lågprisvaruhuset MEJK Lindesberg | C12: 9 | D12: 5 | E12: Bandygatan 2C | F12: 711 34 | G12: Lindesberg | H12: Norr Handlarägd | I12: Mikael Karlsson | J12: 070-6747180 | K12: mikael.karlsson@butikskontakt.se
A13: 10 | B13: Associerad Matköp Tumba Storvreten | C13: 10 | D13: 6 | E13: Storvretsvägen 13 | F13: 147 54 | G13: Tumba | H13: Stockholm 1 Handlarägd | I13: Georgez Tannous | J13: 070-4832987 | K13: georgez.tannous@butikskontakt.se
A14: 11 | B14: Associerad Matvärlden Kungens Kurva | C14: 11 | D14: 7 | E14: Tangentvägen 14 A | F14: 141 75 | G14: Kungens Kurva | H14: Stockholm 2 - Mitt Handlarägd | I14: Muhittin Tayli | J14: 0704-945626 | K14: jt@matvarlden.se ; jonas.tayli@butikskontakt.se
A15: 12 | B15: Associerad Matvärlden Veddesta | C15: 12 | D15: 7 | E15: Nettovägen 2-4 | F15: 175 41 | G15: Järfälla | H15: Stockholm 2 - Mitt Handlarägd | I15: Muhittin Tayli | J15: 0704-945626 | K15: jt@matvarlden.se ; jonas.tayli@butikskontakt.se
... A121: 118 | B121: Hemköp Norrköping Ljura | C121: 118 | D121: 4 | E121: Ljuragatan 1 | F121: 603 51 | G121: Norrköping | H121: Mitt Egenägd | I121: Jimmy Wolffberg | J121: 010-4744232 | K121: butikschef.hemkopnorrkopingljura.4232@hemkop.se
A122: 119 | B122: Hemköp Nossebro C (tidigare 4762) KONKURS | C122: 119 | D122: 12 | E122: Södravägen 2 | F122: 465 31 | G122: Nossebro | H122: Väst Handlarägd
A123: 120 | B123: Hemköp Nyköping C | C123: 120 | D123: 7 | E123: Västra Storgatan 13 | F123: 611 32 | G123: Nyköping | H123: Stockholm 2 - Mitt Handlarägd | I123: Emil Bergkvist | J123: 073 812 75 66 | K123: emil.bergkvist@hemkop.se
A124: 121 | B124: Hemköp Nyköping Spelhagen | C124: 121 | D124: 7 | E124: Arnöleden 5 | F124: 611 31 | G124: Nyköping | H124: Stockholm 2 - Mitt Handlarägd | I124: Robin Ljung & Elin Lundborg | J124: 070-3851970;070-2026208 | K124: jimmy.fagelqvist@hemkop.se; elin.lundborg@hemkop.se;robin.ljungh@hemkop.se
A125: 122 | B125: Hemköp Onsala C | C125: 122 | D125: 11 | E125: Onsala Kyrkby | F125: 439 23 | G125: Onsala | H125: Syd Handlarägd | I125: Jessika Österström | J125: 070-5775089 | K125: jessika.osterstrom@hemkop.se
A126: 123 | B126: Hemköp Oskarström Blåklintsvägen | C126: 123 | D126: 10 | E126: Blåklintsvägen 36 | F126: 313 32 | G126: Oskarström | H126: Syd Egenägd | I126: Gustav Ågren | J126: 010-4744202 | K126: butikschef.hemkoposkarstromblaklintsvagen.4202@hemkop.se
A127: 124 | B127: Hemköp Rättvik C | C127: 124 | D127: 9 | E127: Storgatan 8 | F127: 795 30 | G127: Rättvik | H127: Stockholm-Norr Egenägd | I127: Anders Thynell | J127: 010-4744156 | K127: butikschef.hemkoprattvikc.4156@hemkop.se
A128: 125 | B128: Hemköp Sabis Stockholm Fältöversten | C128: 125 | D128: 6 | E128: Karlaplan 13 | F128: 115 20 | G128: Stockholm | H128: Stockholm 1 Handlarägd | I128: Cecilia Hedman Stenqvist | J128: 073-5252260 | K128: cecilia.hedman.stenqvist@hemkop.se
A129: 126 | B129: Hemköp Saltsjö-Boo Lännersta | C129: 126 | D129: 8 | E129: Prästkragens väg 3 | F129: 132 45 | G129: Saltsjö-Boo | H129: Stockholm Egenägd | I129: Jerker Andersson | J129: 010-4744183 | K129: butikschef.hemkopsaltsjo-boolannersta.4183@hemkop.se
A130: 127 | B130: Hemköp Sjöbo Blentarp | C130: 127 | D130: 11 | E130: Skurupsvägen 1 | F130: 275 61 | G130: Blentarp | H130: Syd Handlarägd | I130: Lars-Erik Gerdin | J130: 070-5716555 | K130: lars-erik.gerdin@hemkop.se
A131: 128 | B131: Hemköp Skillingaryd Artillerigatan | C131: 128 | D131: 10 | E131: Artellerigatan 28 | F131: 568 30 | G131: Skillingaryd | H131: Syd Egenägd | I131: Jennifer Jern Fält | J131: 010-4744307 | K131: butikschef.hemkopskillingarydartillerigatan.4307@hemkop.se
A132: 129 | B132: Hemköp Skövde C | C132: 129 | D132: 4 | E132: Petter Helenes gata 6 | F132: 541 30 | G132: Skövde | H132: Mitt Egenägd | I132: Henrik Hermansson | J132: 010-4744195 | K132: butikschef.hemkopskovdec.4195@hemkop.se
A133: 130 | B133: Hemköp Skövde Hentorp | C133: 130 | D133: 12 | E133: Grönavägen 48 | F133: 54154 S | G133: kövde | H133: Väst Handlarägd | I133: Peter Lindér | J133: 070-7436343 | K133: peter.linder@hemkop.se
A134: 131 | B134: Hemköp Skövde Rydshallen | C134: 131 | D134: 12 | E134: Timmervägen 1 | F134: 541 64 | G134: Skövde | H134: Väst Handlarägd | I134: Peter Lindér | J134: 070-7436343 | K134: peter.linder@hemkop.se
... A223: 220 | B223: Hemköp Östervåla | C223: 220 | D223: 5 | E223: Stora Torget 3:a | F223: 740 46 | G223: Östervåla | H223: Norr Handlarägd | I223: Henrik Olsson | J223: 076-1131178 | K223: henrik.olsson1@hemkop.se

Sheet Objekt i butiker steg 3
A1: Fasta objektimportfält | D1: Metadata
B2: Skapas av Traivo
A3: Objektnamn | B3: Släktnamn | C3: Överordnat objekt | D3: Antal | E3: Tömningsdag | F3: Objekt typ | G3: Färg
A4: Pantkärl | B4: =CONCATENATE(VLOOKUP(C4,'Butiksobjekt steg 2'!A:B,2,FALSE)," ",A4) -> Associerad Börjes Tingsryd Pantkärl | C4: 1 | D4: =RANDBETWEEN(8,53) -> 52 | E4: =RANDBETWEEN(1,5) -> 2 | F4: =A4 -> Pantkärl | G4: Grön
A5: Matavfallskärl | B5: =CONCATENATE(VLOOKUP(C5,'Butiksobjekt steg 2'!A:B,2,FALSE)," ",A5) -> Associerad Börjes Tingsryd Matavfallskärl | C5: 1 | D5: =RANDBETWEEN(8,53) -> 27 | E5: =RANDBETWEEN(1,5) -> 1 | F5: =A5 -> Matavfallskärl | G5: Blå
A6: Pantkärl | B6: =CONCATENATE(VLOOKUP(C6,'Butiksobjekt steg 2'!A:B,2,FALSE)," ",A6) -> Associerad Extra Mjällby Listerlandet Pantkärl | C6: 2 | D6: =RANDBETWEEN(8,53) -> 8 | E6: =RANDBETWEEN(1,5) -> 4 | F6: =A6 -> Pantkärl | G6: Brun
A7: Matavfallskärl | B7: =CONCATENATE(VLOOKUP(C7,'Butiksobjekt steg 2'!A:B,2,FALSE)," ",A7) -> Associerad Extra Mjällby Listerlandet Matavfallskärl | C7: 2 | D7: =RANDBETWEEN(8,53) -> 49 | E7: =RANDBETWEEN(1,5) -> 3 | F7: =A7 -> Matavfallskärl | G7: Grön
A8: Kuundvagnsgarage | B8: =CONCATENATE(VLOOKUP(C8,'Butiksobjekt steg 2'!A:B,2,FALSE)," ",A8) -> Associerad Extra Mjällby Listerlandet Kuundvagnsgarage | C8: 2 | D8: =RANDBETWEEN(8,53) -> 8 | E8: =RANDBETWEEN(1,5) -> 3 | F8: =A8 -> Kuundvagnsgarage | G8: Blå
A9: Pantkärl | B9: =CONCATENATE(VLOOKUP(C9,'Butiksobjekt steg 2'!A:B,2,FALSE)," ",A9) -> Associerad Fittja Matmarknad Norsborg Pantkärl | C9: 3 | D9: =RANDBETWEEN(8,53) -> 27 | E9: =RANDBETWEEN(1,5) -> 4 | F9: =A9 -> Pantkärl | G9: Brun
A10: Matavfallskärl | B10: =CONCATENATE(VLOOKUP(C10,'Butiksobjekt steg 2'!A:B,2,FALSE)," ",A10) -> Associerad Fittja Matmarknad Norsborg Matavfallskärl | C10: 3 | D10: =RANDBETWEEN(8,53) -> 24 | E10: =RANDBETWEEN(1,5) -> 1 | F10: =A10 -> Matavfallskärl | G10: Grön
A11: Kuundvagnsgarage | B11: =CONCATENATE(VLOOKUP(C11,'Butiksobjekt steg 2'!A:B,2,FALSE)," ",A11) -> Associerad Fittja Matmarknad Norsborg Kuundvagnsgarage | C11: 3 | D11: =RANDBETWEEN(8,53) -> 14 | E11: =RANDBETWEEN(1,5) -> 3 | F11: =A11 -> Kuundvagnsgarage | G11: Blå
A12: Pantkärl | B12: =CONCATENATE(VLOOKUP(C12,'Butiksobjekt steg 2'!A:B,2,FALSE)," ",A12) -> Associerad Fresha Stockholm Hässelby Pantkärl | C12: 4 | D12: =RANDBETWEEN(8,53) -> 27 | E12: =RANDBETWEEN(1,5) -> 1 | F12: =A12 -> Pantkärl | G12: Brun
A13: Matavfallskärl | B13: =CONCATENATE(VLOOKUP(C13,'Butiksobjekt steg 2'!A:B,2,FALSE)," ",A13) -> Associerad Fresha Stockholm Hässelby Matavfallskärl | C13: 4 | D13: =RANDBETWEEN(8,53) -> 18 | E13: =RANDBETWEEN(1,5) -> 4 | F13: =A13 -> Matavfallskärl | G13: Grön
A14: Kuundvagnsgarage | B14: =CONCATENATE(VLOOKUP(C14,'Butiksobjekt steg 2'!A:B,2,FALSE)," ",A14) -> Associerad Fresha Stockholm Hässelby Kuundvagnsgarage | C14: 4 | D14: =RANDBETWEEN(8,53) -> 37 | E14: =RANDBETWEEN(1,5) -> 4 | F14: =A14 -> Kuundvagnsgarage | G14: Blå
A15: Pantkärl | B15: =CONCATENATE(VLOOKUP(C15,'Butiksobjekt steg 2'!A:B,2,FALSE)," ",A15) -> Associerad Hemköp Gråbo Bonum Pantkärl | C15: 5 | D15: =RANDBETWEEN(8,53) -> 18 | E15: =RANDBETWEEN(1,5) -> 3 | F15: =A15 -> Pantkärl | G15: Brun
... A662: Kuundvagnsgarage | B662: =CONCATENATE(VLOOKUP(C662,'Butiksobjekt steg 2'!A:B,2,FALSE)," ",A662) -> Hemköp Östervåla Kuundvagnsgarage | C662: 220 | D662: =RANDBETWEEN(8,53) -> 49 | E662: =RANDBETWEEN(1,5) -> 5 | F662: =A662 -> Kuundvagnsgarage | G662: Blå

Sheet Metadatareferenser
A1: Metadataområde | B1: Ref assosiations Namn | C1: Nummer | D1: Beskrivning | E1: Dataformat | F1: Datafält | G1: Fasta val | H1: Nivålåst | I1: Tillåt dubletter | J1: Kronologisk visning
A2: Grunduppgifter | B2: Kontakt | C2: 1 | D2: Namn på kontaktperson | E2: Alfanumeriskt | F2: Förnmn, efternamn, Titel, Företag, telefon, e-post | G2: Nej | H2: Nej | I2: Ja | J2: ja
A3: Grunduppgifter | B3: Vinjetbild | C3: 3 | D3: Bild på objekt | E3: JPG | F3: Bildfilrefferens | G3: Nej | H3: Ja | I3: Nej | J3: Ja
A4: Produktion | B4: Typ | C4: 6 | D4: Objekttyp | E4: Alfanumeriskt | F4: Objektyp | G4: Nej | H4: Ja | I4: Ja | J4: ja
A5: Produktion | B5: Antal | C5: 9 | D5: Antal | E5: Numeriskt | F5: antal | G5: Nej | H5: Ja | I5: Nej | J5: Ja
A6: Produktion | B6: Yta | C6: 12 | D6: Antal m2 | E6: Numeriskt | F6: antal m2 | G6: Nej
A7: Produktion | B7: Storlek | C7: 15 | D7: 3 storlekar | E7: Alfanumeriskt | F7: Smal/medium/large | G7: Ja
A8: Status | B8: Lyftkrok | C8: 18 | D8: Kontroll lyftkrok
A9: Grunduppgifter | C9: 21
A10: Grunduppgifter | C10: 24
A11: Grunduppgifter | C11: 27
A12: Grunduppgifter | B12: Objektnamn | C12: 1000 | D12: Objektnamn mandatory systemfält | E12: Alfanumeriskt | F12: Namn som bildar släktnamn med överordnat | G12: Nej | H12: Ja | I12: Nej | J12: ja
